<?xml version="1.0" ?>
<!-- =================================================================================== -->
<!-- |    This document was autogenerated by xacro from ./models/multicopters/xacro/multicopter_0.xacro | -->
<!-- |    EDITING THIS FILE BY HAND IS NOT RECOMMENDED                                 | -->
<!-- =================================================================================== -->
<robot name="multicopter_0">
  <!-- <origin xyz="0.0 0.0 0.053302" rpy="0 0 0" /> -->
  <origin rpy="0 0 0" xyz="0.0 0.0 2.0"/>
  <link name="multicopter_0/base_link">
    <inertial>
      <mass value="1.5"/>
      <inertia ixx="0.0347563" ixy="0" ixz="0" iyy="0.07" iyz="0" izz="0.0977"/>
    </inertial>
    <visual>
      <geometry>
        <mesh filename="https://fuel.gazebosim.org/1.0/openrobotics/models/x3 uav/4/files/meshes/x3.dae" scale="1 1 1"/>
      </geometry>
    </visual>
    <collision>
      <geometry>
        <box size="0.47 0.47 0.11"/>
      </geometry>
    </collision>
  </link>
  <link name="multicopter_0/rotor_0">
    <inertial>
      <mass value="0.005"/>
      <inertia ixx="9.75e-07" ixy="0" ixz="0" iyy="4.17041e-05" iyz="0" izz="4.26041e-05"/>
    </inertial>
    <visual>
      <geometry>
        <mesh filename="https://fuel.gazebosim.org/1.0/openrobotics/models/x3 uav/4/files/meshes/propeller_ccw.dae" scale="0.1 0.1 0.1"/>
      </geometry>
      <material name="Gazebo/Blue">
        <texture filename="file://media/materials/scripts/gazebo.material"/>
      </material>
    </visual>
    <collision>
      <geometry>
        <cylinder length="0.005" radius="0.1"/>
      </geometry>
    </collision>
  </link>
  <joint name="multicopter_0/rotor_0_joint" type="revolute">
    <origin rpy="0 0 0" xyz="0.13 -0.22 0.023"/>
    <parent link="multicopter_0/base_link"/>
    <child link="multicopter_0/rotor_0"/>
    <axis xyz="0 0 1"/>
    <limit effort="1.79769e+308" lower="-1e+16" upper="1e+16" velocity="1.79769e+308"/>
    <!-- <dynamics /> -->
  </joint>
  <link name="multicopter_0/rotor_1">
    <inertial>
      <mass value="0.005"/>
      <inertia ixx="9.75e-07" ixy="0" ixz="0" iyy="4.17041e-05" iyz="0" izz="4.26041e-05"/>
    </inertial>
    <visual>
      <geometry>
        <mesh filename="https://fuel.gazebosim.org/1.0/openrobotics/models/x3 uav/4/files/meshes/propeller_ccw.dae" scale="0.1 0.1 0.1"/>
      </geometry>
      <material name="Gazebo/Blue">
        <texture filename="file://media/materials/scripts/gazebo.material"/>
      </material>
    </visual>
    <collision>
      <geometry>
        <cylinder length="0.005" radius="0.1"/>
      </geometry>
    </collision>
  </link>
  <joint name="multicopter_0/rotor_1_joint" type="revolute">
    <origin rpy="0 0 0" xyz="-0.13 0.2 0.023"/>
    <parent link="multicopter_0/base_link"/>
    <child link="multicopter_0/rotor_1"/>
    <axis xyz="0 0 1"/>
    <limit effort="1.79769e+308" lower="-1e+16" upper="1e+16" velocity="1.79769e+308"/>
    <!-- <dynamics /> -->
  </joint>
  <link name="multicopter_0/rotor_2">
    <inertial>
      <mass value="0.005"/>
      <inertia ixx="9.75e-07" ixy="0" ixz="0" iyy="4.17041e-05" iyz="0" izz="4.26041e-05"/>
    </inertial>
    <visual>
      <geometry>
        <mesh filename="https://fuel.gazebosim.org/1.0/openrobotics/models/x3 uav/4/files/meshes/propeller_ccw.dae" scale="0.1 0.1 0.1"/>
      </geometry>
      <material name="Gazebo/Blue">
        <texture filename="file://media/materials/scripts/gazebo.material"/>
      </material>
    </visual>
    <collision>
      <geometry>
        <cylinder length="0.005" radius="0.1"/>
      </geometry>
    </collision>
  </link>
  <joint name="multicopter_0/rotor_2_joint" type="revolute">
    <origin rpy="0 0 0" xyz="0.13 0.22 0.023"/>
    <parent link="multicopter_0/base_link"/>
    <child link="multicopter_0/rotor_2"/>
    <axis xyz="0 0 1"/>
    <limit effort="1.79769e+308" lower="-1e+16" upper="1e+16" velocity="1.79769e+308"/>
    <!-- <dynamics /> -->
  </joint>
  <link name="multicopter_0/rotor_3">
    <inertial>
      <mass value="0.005"/>
      <inertia ixx="9.75e-07" ixy="0" ixz="0" iyy="4.17041e-05" iyz="0" izz="4.26041e-05"/>
    </inertial>
    <visual>
      <geometry>
        <mesh filename="https://fuel.gazebosim.org/1.0/openrobotics/models/x3 uav/4/files/meshes/propeller_ccw.dae" scale="0.1 0.1 0.1"/>
      </geometry>
      <material name="Gazebo/Blue">
        <texture filename="file://media/materials/scripts/gazebo.material"/>
      </material>
    </visual>
    <collision>
      <geometry>
        <cylinder length="0.005" radius="0.1"/>
      </geometry>
    </collision>
  </link>
  <joint name="multicopter_0/rotor_3_joint" type="revolute">
    <origin rpy="0 0 0" xyz="-0.13 -0.2 0.023"/>
    <parent link="multicopter_0/base_link"/>
    <child link="multicopter_0/rotor_3"/>
    <axis xyz="0 0 1"/>
    <limit effort="1.79769e+308" lower="-1e+16" upper="1e+16" velocity="1.79769e+308"/>
    <!-- <dynamics /> -->
  </joint>
  <gazebo>
    <static>false</static>
    <enable_wind>true</enable_wind>
    <plugin filename="ignition-gazebo-multicopter-motor-model-system" name="gz::sim::systems::MulticopterMotorModel">
      <robotNamespace>multicopter_0</robotNamespace>
      <jointName>multicopter_0/rotor_0_joint</jointName>
      <linkName>multicopter_0/rotor_0</linkName>
      <turningDirection>ccw</turningDirection>
      <timeConstantUp>0.0125</timeConstantUp>
      <timeConstantDown>0.025</timeConstantDown>
      <maxRotVelocity>800.0</maxRotVelocity>
      <motorConstant>8.54858e-06</motorConstant>
      <momentConstant>0.016</momentConstant>
      <commandSubTopic>gazebo/command/motor_speed</commandSubTopic>
      <motorNumber>0</motorNumber>
      <rotorDragCoefficient>8.06428e-05</rotorDragCoefficient>
      <rollingMomentCoefficient>1e-06</rollingMomentCoefficient>
      <motorSpeedPubTopic>motor_speed/0</motorSpeedPubTopic>
      <rotorVelocitySlowdownSim>10</rotorVelocitySlowdownSim>
      <motorType>velocity</motorType>
    </plugin>
    <plugin filename="ignition-gazebo-multicopter-motor-model-system" name="gz::sim::systems::MulticopterMotorModel">
      <robotNamespace>multicopter_0</robotNamespace>
      <jointName>multicopter_0/rotor_1_joint</jointName>
      <linkName>multicopter_0/rotor_1</linkName>
      <turningDirection>ccw</turningDirection>
      <timeConstantUp>0.0125</timeConstantUp>
      <timeConstantDown>0.025</timeConstantDown>
      <maxRotVelocity>800.0</maxRotVelocity>
      <motorConstant>8.54858e-06</motorConstant>
      <momentConstant>0.016</momentConstant>
      <commandSubTopic>gazebo/command/motor_speed</commandSubTopic>
      <motorNumber>1</motorNumber>
      <rotorDragCoefficient>8.06428e-05</rotorDragCoefficient>
      <rollingMomentCoefficient>1e-06</rollingMomentCoefficient>
      <motorSpeedPubTopic>motor_speed/1</motorSpeedPubTopic>
      <rotorVelocitySlowdownSim>10</rotorVelocitySlowdownSim>
      <motorType>velocity</motorType>
    </plugin>
    <plugin filename="ignition-gazebo-multicopter-motor-model-system" name="gz::sim::systems::MulticopterMotorModel">
      <robotNamespace>multicopter_0</robotNamespace>
      <jointName>multicopter_0/rotor_2_joint</jointName>
      <linkName>multicopter_0/rotor_2</linkName>
      <turningDirection>cw</turningDirection>
      <timeConstantUp>0.0125</timeConstantUp>
      <timeConstantDown>0.025</timeConstantDown>
      <maxRotVelocity>800.0</maxRotVelocity>
      <motorConstant>8.54858e-06</motorConstant>
      <momentConstant>0.016</momentConstant>
      <commandSubTopic>gazebo/command/motor_speed</commandSubTopic>
      <motorNumber>2</motorNumber>
      <rotorDragCoefficient>8.06428e-05</rotorDragCoefficient>
      <rollingMomentCoefficient>1e-06</rollingMomentCoefficient>
      <motorSpeedPubTopic>motor_speed/2</motorSpeedPubTopic>
      <rotorVelocitySlowdownSim>10</rotorVelocitySlowdownSim>
      <motorType>velocity</motorType>
    </plugin>
    <plugin filename="ignition-gazebo-multicopter-motor-model-system" name="gz::sim::systems::MulticopterMotorModel">
      <robotNamespace>multicopter_0</robotNamespace>
      <jointName>multicopter_0/rotor_3_joint</jointName>
      <linkName>multicopter_0/rotor_3</linkName>
      <turningDirection>cw</turningDirection>
      <timeConstantUp>0.0125</timeConstantUp>
      <timeConstantDown>0.025</timeConstantDown>
      <maxRotVelocity>800.0</maxRotVelocity>
      <motorConstant>8.54858e-06</motorConstant>
      <momentConstant>0.016</momentConstant>
      <commandSubTopic>gazebo/command/motor_speed</commandSubTopic>
      <motorNumber>3</motorNumber>
      <rotorDragCoefficient>8.06428e-05</rotorDragCoefficient>
      <rollingMomentCoefficient>1e-06</rollingMomentCoefficient>
      <motorSpeedPubTopic>motor_speed/3</motorSpeedPubTopic>
      <rotorVelocitySlowdownSim>10</rotorVelocitySlowdownSim>
      <motorType>velocity</motorType>
    </plugin>
    <plugin filename="ignition-gazebo-multicopter-control-system" name="gz::sim::systems::MulticopterVelocityControl">
      <robotNamespace>multicopter_0</robotNamespace>
      <commandSubTopic>gazebo/command/twist</commandSubTopic>
      <enableSubTopic>enable</enableSubTopic>
      <comLinkName>multicopter_0/base_link</comLinkName>
      <velocityGain>2.7 2.7 2.7</velocityGain>
      <attitudeGain>2 3 0.15</attitudeGain>
      <angularRateGain>0.4 0.52 0.18</angularRateGain>
      <maximumLinearAcceleration>2 2 2</maximumLinearAcceleration>
      <rotorConfiguration>
        <rotor>
          <jointName>multicopter_0/rotor_0_joint</jointName>
          <forceConstant>8.54858e-06</forceConstant>
          <momentConstant>0.016</momentConstant>
          <direction>1</direction>
        </rotor>
        <rotor>
          <jointName>multicopter_0/rotor_1_joint</jointName>
          <forceConstant>8.54858e-06</forceConstant>
          <momentConstant>0.016</momentConstant>
          <direction>1</direction>
        </rotor>
        <rotor>
          <jointName>multicopter_0/rotor_2_joint</jointName>
          <forceConstant>8.54858e-06</forceConstant>
          <momentConstant>0.016</momentConstant>
          <direction>-1</direction>
        </rotor>
        <rotor>
          <jointName>multicopter_0/rotor_3_joint</jointName>
          <forceConstant>8.54858e-06</forceConstant>
          <momentConstant>0.016</momentConstant>
          <direction>-1</direction>
        </rotor>
      </rotorConfiguration>
    </plugin>
    <plugin filename="ignition-gazebo-odometry-publisher-system" name="ignition::gazebo::systems::OdometryPublisher">
      <dimensions>3</dimensions>
    </plugin>
    <plugin filename="ignition-gazebo-comms-endpoint-system" name="ignition::gazebo::systems::CommsEndpoint">
      <address>multicopter_0</address>
      <topic>multicopter_0/rx</topic>
    </plugin>
  </gazebo>
</robot>
