<?xml version="1.0"?>
<robot xmlns:xacro="http://ros.org/wiki/xacro">
  <xacro:macro name="base" params="name">
    <link name="${name}/base_link">
      <inertial>
        <mass value="1.5" />
        <inertia 
          ixx="0.0347563" 
          ixy="0" 
          ixz="0" 
          iyy="0.07" 
          iyz="0" 
          izz="0.0977"
        />
      </inertial>
      
      <visual>
        <geometry>
          <mesh filename="https://fuel.gazebosim.org/1.0/openrobotics/models/x3 uav/4/files/meshes/x3.dae" scale="1 1 1"/>
        </geometry>
      </visual>

      <collision>
        <geometry>
          <box size="0.47 0.47 0.11"/>
        </geometry>
      </collision>
    </link>
  </xacro:macro>

  <xacro:macro name="rotor" params="name num rel_pos rel_rot">
    <link name="${name}/rotor_${num}">
      <inertial>
        <mass value="0.005"/>
        <inertia 
          ixx="9.75e-07" 
          ixy="0" 
          ixz="0" 
          iyy="4.17041e-05" 
          iyz="0" 
          izz="4.26041e-05"
        />
      </inertial>
      <visual>
        <geometry>
          <mesh filename="https://fuel.gazebosim.org/1.0/openrobotics/models/x3 uav/4/files/meshes/propeller_ccw.dae" scale="0.1 0.1 0.1"/>
        </geometry>
        <material name="Gazebo/Blue">
          <texture filename="file://media/materials/scripts/gazebo.material"/>
        </material>
      </visual>
      <collision>
        <geometry>
          <cylinder radius="0.1" length="0.005"/>
        </geometry>
      </collision>
    </link>

    <joint name="${name}/rotor_${num}_joint" type='revolute'>
      <origin xyz="${rel_pos}" rpy="${rel_rot}"/>
      <parent link="${name}/base_link"/>
      <child link="${name}/rotor_${num}"/>
      <axis xyz="0 0 1"/>
      <limit lower="-1e+16" upper="1e+16" effort="1.79769e+308" velocity="1.79769e+308"/>
      <!-- <dynamics /> -->
    </joint>
  </xacro:macro>

  <xacro:macro name="multicopter-motor-model-system" params="name num turning_direction">
    <plugin
      filename="ignition-gazebo-multicopter-motor-model-system"
      name="gz::sim::systems::MulticopterMotorModel">
      <robotNamespace>${name}</robotNamespace>
      <jointName>${name}/rotor_${num}_joint</jointName>
      <linkName>${name}/rotor_${num}</linkName>
      <turningDirection>${turning_direction}</turningDirection>
      <timeConstantUp>0.0125</timeConstantUp>
      <timeConstantDown>0.025</timeConstantDown>
      <maxRotVelocity>800.0</maxRotVelocity>
      <motorConstant>8.54858e-06</motorConstant>
      <momentConstant>0.016</momentConstant>
      <commandSubTopic>gazebo/command/motor_speed</commandSubTopic>
      <motorNumber>${num}</motorNumber>
      <rotorDragCoefficient>8.06428e-05</rotorDragCoefficient>
      <rollingMomentCoefficient>1e-06</rollingMomentCoefficient>
      <motorSpeedPubTopic>motor_speed/${num}</motorSpeedPubTopic>
      <rotorVelocitySlowdownSim>10</rotorVelocitySlowdownSim>
      <motorType>velocity</motorType>
    </plugin>
  </xacro:macro>

  <xacro:macro name="rotor-config" params="name num direction">
    <rotor>
      <jointName>${name}/rotor_${num}_joint</jointName>
      <forceConstant>8.54858e-06</forceConstant>
      <momentConstant>0.016</momentConstant>
      <direction>${direction}</direction>
    </rotor>
  </xacro:macro>

  <xacro:macro name="gazebo" params="name">
    <gazebo>
      <static>false</static>
      <enable_wind>true</enable_wind>
      <xacro:multicopter-motor-model-system name="${name}" num="0" turning_direction="ccw"/>
      <xacro:multicopter-motor-model-system name="${name}" num="1" turning_direction="ccw"/>
      <xacro:multicopter-motor-model-system name="${name}" num="2" turning_direction="cw"/>
      <xacro:multicopter-motor-model-system name="${name}" num="3" turning_direction="cw"/>
      <plugin
        filename="ignition-gazebo-multicopter-control-system"
        name="gz::sim::systems::MulticopterVelocityControl">
        <robotNamespace>${name}</robotNamespace>
        <commandSubTopic>gazebo/command/twist</commandSubTopic>
        <enableSubTopic>enable</enableSubTopic>
        <comLinkName>${name}/base_link</comLinkName>
        <velocityGain>2.7 2.7 2.7</velocityGain>
        <attitudeGain>2 3 0.15</attitudeGain>
        <angularRateGain>0.4 0.52 0.18</angularRateGain>
        <maximumLinearAcceleration>2 2 2</maximumLinearAcceleration>
        <rotorConfiguration>
          <xacro:rotor-config name="${name}" num="0" direction="1"/>
          <xacro:rotor-config name="${name}" num="1" direction="1"/>
          <xacro:rotor-config name="${name}" num="2" direction="-1"/>
          <xacro:rotor-config name="${name}" num="3" direction="-1"/>
        </rotorConfiguration>
      </plugin>
      <plugin
        filename="ignition-gazebo-odometry-publisher-system"
        name="ignition::gazebo::systems::OdometryPublisher">
        <dimensions>3</dimensions>
      </plugin>
      <plugin
        filename="ignition-gazebo-comms-endpoint-system"
        name="ignition::gazebo::systems::CommsEndpoint">
        <address>${name}</address>
        <topic>${name}/rx</topic>
      </plugin>
    </gazebo>
  </xacro:macro>
</robot>