<?xml version="1.0" ?>
<!-- =================================================================================== -->
<!-- |    This document was autogenerated by xacro from ./models/ugvs/xacro/ugv_0.xacro | -->
<!-- |    EDITING THIS FILE BY HAND IS NOT RECOMMENDED                                 | -->
<!-- =================================================================================== -->
<robot name="uvg_0">
  <material name="red">
    <color rgba="1.0 0.0 0.0 1"/>
  </material>
  <material name="green">
    <color rgba="0.0 1.0 0.0 1"/>
  </material>
  <material name="blue">
    <color rgba="0.0 0.0 1.0 1"/>
  </material>
  <!-- pose -->
  <origin rpy="0 0 0" xyz="2.0 0.0 0.5"/>
  <link name="chassis_link">
    <inertial>
      <mass value="10.0"/>
      <inertia ixx="1.0416666666666665" ixy="0" ixz="0" iyy="4.166666666666666" iyz="0" izz="3.5416666666666665"/>
    </inertial>
    <visual>
      <geometry>
        <box size="2.0 1.0 0.5"/>
      </geometry>
      <material name="blue"/>
    </visual>
    <collision>
      <geometry>
        <box size="2.0 1.0 0.5"/>
      </geometry>
    </collision>
  </link>
  <link name="left_rear_wheel_link">
    <inertial>
      <mass value="2.0"/>
      <inertia ixx="0.08666666666666668" ixy="0" ixz="0" iyy="0.08666666666666668" iyz="0" izz="0.16000000000000003"/>
    </inertial>
    <visual>
      <geometry>
        <cylinder length="0.2" radius="0.4"/>
      </geometry>
      <material name="red"/>
    </visual>
    <collision>
      <geometry>
        <cylinder length="0.2" radius="0.4"/>
      </geometry>
    </collision>
  </link>
  <joint name="left_rear_wheel_joint" type="revolute">
    <origin rpy="-1.5707963267948966 0 0" xyz="-0.5 0.6 0"/>
    <parent link="chassis_link"/>
    <child link="left_rear_wheel_link"/>
    <axis xyz="0 0 1"/>
    <limit effort="1.79769e+308" lower="-1.79769e+308" upper="1.79769e+308" velocity="1.79769e+308"/>
  </joint>
  <link name="right_rear_wheel_link">
    <inertial>
      <mass value="2.0"/>
      <inertia ixx="0.08666666666666668" ixy="0" ixz="0" iyy="0.08666666666666668" iyz="0" izz="0.16000000000000003"/>
    </inertial>
    <visual>
      <geometry>
        <cylinder length="0.2" radius="0.4"/>
      </geometry>
      <material name="red"/>
    </visual>
    <collision>
      <geometry>
        <cylinder length="0.2" radius="0.4"/>
      </geometry>
    </collision>
  </link>
  <joint name="right_rear_wheel_joint" type="revolute">
    <origin rpy="-1.5707963267948966 0 0" xyz="-0.5 -0.6 0"/>
    <parent link="chassis_link"/>
    <child link="right_rear_wheel_link"/>
    <axis xyz="0 0 1"/>
    <limit effort="1.79769e+308" lower="-1.79769e+308" upper="1.79769e+308" velocity="1.79769e+308"/>
  </joint>
  <link name="caster_link">
    <inertial>
      <mass value="1.0"/>
      <inertia ixx="0.016000000000000004" ixy="0" ixz="0" iyy="0.016000000000000004" iyz="0" izz="0.016000000000000004"/>
    </inertial>
    <visual>
      <geometry>
        <sphere radius="0.2"/>
      </geometry>
      <material name="green"/>
    </visual>
    <collision>
      <geometry>
        <sphere radius="0.2"/>
      </geometry>
    </collision>
  </link>
  <joint name="caster_wheel_joint" type="continuous">
    <origin rpy="0 0 0" xyz="0.8 0 -0.2"/>
    <parent link="chassis_link"/>
    <child link="caster_link"/>
  </joint>
  <gazebo>
    <static>false</static>
    <plugin filename="libignition-gazebo-diff-drive-system.so" name="ignition::gazebo::systems::DiffDrive">
      <left_joint>left_rear_wheel_joint</left_joint>
      <right_joint>right_rear_wheel_joint</right_joint>
      <wheel_separation>1.2</wheel_separation>
      <wheel_radius>0.4</wheel_radius>
      <odom_publish_frequency>1</odom_publish_frequency>
      <topic>cmd_vel</topic>
    </plugin>
    <plugin filename="ignition-gazebo-comms-endpoint-system" name="ignition::gazebo::systems::CommsEndpoint">
      <address>ugv_0</address>
      <topic>ugv_0/rx</topic>
    </plugin>
  </gazebo>
</robot>
